<?xml version="1.0"?>

<robot name="p1" xmlns:xacro="http://ros.org/wiki/xacro">
    <xacro:property name="pi" value="3.1415"/>

    <material name="red">
        <color rgba="1 0 0 1"/>
    </material>

    <material name="green">
        <color rgba="0 1 0 1"/>
    </material>

    <material name="blue">
        <color rgba="0 0 0.8 1"/>
    </material>

    <material name="black">
        <color rgba="0 0 0 1"/>
    </material>

    <xacro:macro name="default_inertial" params="mass">
    <inertial>
      <mass value="${mass}" />
      <inertia ixx="1.0" ixy="0.0" ixz="0.0" iyy="1.0" iyz="0.0" izz="1.0" />
    </inertial>
  </xacro:macro>
    
     <link name="dummy"></link>
    <!--I want to add a base link-->
    <link name="base_link">
        <visual>
            <geometry>
                <cylinder radius="0.10" length="0.01"/>
            </geometry>
            <material name="black"/>
        </visual>
        <collision>
            <geometry>
               <cylinder radius="0.10" length="0.01"/>
            </geometry>
        </collision>
        <xacro:default_inertial mass="25"/>
    </link>

    <link name="link1">
        <visual>
            <origin xyz="0 0 0.25" rpy="0 0 0 "/>
            <geometry>
                <cylinder radius="0.02" length="0.5"/>
            </geometry>
            <material name="red"/>
        </visual>
        <collision>
            <origin xyz="0 0 0.25" rpy="0 0 0 "/>
            <geometry>
                <cylinder radius="0.02" length="0.5"/>
            </geometry>
        </collision>
        <xacro:default_inertial mass="1"/>
    </link>

    <link name="link2">
        
        <visual>
            <origin xyz="0 0.25 0.0" rpy="${pi/2} 0 0 "/>
            <geometry>
                <cylinder radius="0.02" length="0.5"/>
            </geometry>
            <material name="green"/>
        </visual>
        <collision>
            <origin xyz="0 0.25 0.0" rpy="${pi/2} 0 0.0"/>
            <geometry>
                <cylinder radius="0.02" length="0.5"/>
            </geometry>
        </collision>
        <xacro:default_inertial mass="1"/>
    </link>

    <link name="link3">
        <visual>
            <origin xyz="0 0.25 0" rpy="${pi/2} 0 0"/>
            <geometry>
                <cylinder radius="0.02" length="0.5"/>
            </geometry>
            <material name="blue"/>
        </visual>
        <collision>
            <origin xyz="0 0.25 0" rpy="${pi/2} 0 0"/>
            <geometry>
                <cylinder radius="0.02" length="0.5"/>
            </geometry>
        </collision>
        <xacro:default_inertial mass="1"/>
    </link>

    <link name="link4">
        <visual>
            <geometry>
                <box size="0.08 0.08 0.08"/>
            </geometry>
            <material name="black"/>
        </visual>
        <collision>
            <geometry>
                <box size="0.08 0.08 0.08"/>
            </geometry>
        </collision>
        <xacro:default_inertial mass="1"/>
    </link>

    <link name="link5">
        <visual>
            <origin xyz="0 0 0.125" rpy="0 0 0"/>
            <geometry>
                <cylinder radius="0.01" length="0.25"/>
            </geometry>
            <material name="red"/>
        </visual>
        <collision>
            <origin xyz="0 0 0.125" rpy="0 0 0"/>
            <geometry>
                <cylinder radius="0.01" length="0.25"/>
            </geometry>
        </collision>
        <xacro:default_inertial mass="1"/>
    </link>

    

    <!-- JOINT STUFF-->

    <joint name="joint5" type="fixed">
        <origin xyz="0 0 0" rpy="0 0 0"/>
        <parent link="base_link"/>
        <child link="link5"/>
    </joint>

    <joint name="dummy_joint" type="fixed">
        <parent link="dummy"/>
        <child link="base_link"/>
    </joint>

    <joint name="joint1" type="prismatic">
        <origin xyz="0 0 0" rpy="0 0 0"/>
        <parent link="base_link"/>
        <child link="link1"/>
        <axis xyz="0 0 1"/>
        <limit lower="0" upper="0.25" effort="10" velocity="1"/>
       
    </joint>

    <joint name="joint2" type="revolute">
        <origin xyz="0 0.0 0.5" rpy="0 0 0"/>
        <parent link="link1"/>
        <child link="link2"/>
        <axis xyz="0 0 1"/>
        <limit lower="${-pi/2}" upper="${pi/2}" effort="10" velocity="1"/>
        
    </joint>

    <joint name="joint3" type="revolute">
        <origin xyz="0 0.5 0." rpy="${pi/2} 0 ${pi/2}"/>
        <parent link="link2"/>
        <child link="link3"/>
        <axis xyz="0 0 1"/>
        <limit lower="${-3*pi/2}" upper="${-pi/2}" effort="10" velocity="1"/>
       
    </joint>

    <joint name="joint4" type="revolute">
        <origin xyz="0 0.5 0" rpy="${-pi/2} 0 0"/>
        <parent link="link3"/>
        <child link="link4"/>
        <axis xyz="0 0 1"/>
        <limit lower="${-pi/2}" upper="${pi/2}" effort="10" velocity="1"/>
        
    </joint>

    
    <!--TRANS STUFF-->

    <transmission name="trans1">
        <type>transmission_interface/SimpleTransmission</type>
        <actuator name="$joint1_motor">
            <mechanicalReduction>1</mechanicalReduction>
        </actuator>
        <joint name="joint1">
            <hardwareInterface>hardware_interface/PositionJointInterface</hardwareInterface>
        </joint>
    </transmission>

    <transmission name="trans2">
        <type>transmission_interface/SimpleTransmission</type>
        <actuator name="$joint2_motor">
            <mechanicalReduction>1</mechanicalReduction>
        </actuator>
        <joint name="joint2">
            <hardwareInterface>hardware_interface/PositionJointInterface</hardwareInterface>
        </joint>
    </transmission>

    <transmission name="trans3">
        <type>transmission_interface/SimpleTransmission</type>
        <actuator name="$joint3_motor">
            <mechanicalReduction>1</mechanicalReduction>
        </actuator>
        <joint name="joint3">
            <hardwareInterface>hardware_interface/PositionJointInterface</hardwareInterface>
        </joint>
    </transmission>

    <transmission name="trans4">
        <type>transmission_interface/SimpleTransmission</type>
        <actuator name="$joint4_motor">
            <mechanicalReduction>1</mechanicalReduction>
        </actuator>
        <joint name="joint4">
            <hardwareInterface>hardware_interface/PositionJointInterface</hardwareInterface>
        </joint>
    </transmission>

     <gazebo>
        <plugin name="gazebo_ros_control" filename="libgazebo_ros_control.so">
        <robotNamespace>/</robotNamespace>
        </plugin>
    </gazebo>

   
    <xacro:include filename="$(find robotics)/robotics_description/urdf/p1.gazebo" />

</robot>
